<?xml version="1.0" encoding="utf-8"?>
<robot name="rover_description" xmlns:xacro="http://wiki.ros.org/xacro">

  <xacro:arg name="is_ignition" default="true" />
  <xacro:arg name="use_sim_time" default="true" />
  
  <!-- Include the gazebo functionality -->
  <xacro:include filename="$(find rover_description)/urdf/rover_gazebo.xacro" />
  
  <link name="base_footprint"/>

  <joint name="base_joint" type="fixed">
    <origin xyz="0 0 0.20504" rpy="0 0 0"/>
    <parent link="base_footprint"/>
    <child link="base_link"/>
  </joint>
   
  <link
    name="base_link">
    <inertial>
      <origin
        xyz="-0.0355623533286835 -2.22044604925031E-16 0.0164166426332336"
        rpy="0 0 0" />
      <mass
        value="11.4311847158193" />
      <inertia
        ixx="0.15921041630405"
        ixy="-1.96548467063328E-17"
        ixz="0.00978928264057675"
        iyy="0.356433283334057"
        iyz="-2.51404195233332E-17"
        izz="0.453550833652058" />
    </inertial>
    <visual>
      <origin
        xyz="0 0 0"
        rpy="0 0 0" />
      <geometry>
        <mesh
          filename="package://rover_description/meshes/base_link.STL" />
      </geometry>
      <material
        name="">
        <color
          rgba="0.792156862745098 0.819607843137255 0.933333333333333 1" />
      </material>
    </visual>
    <collision>
      <origin
        xyz="0 0 0"
        rpy="0 0 0" />
      <geometry>
        <mesh
          filename="package://rover_description/meshes/base_link.STL" />
      </geometry>
    </collision>
  </link>
  <link
    name="link_FL">
    <inertial>
      <origin
        xyz="-2.2204E-16 -0.02376 1.1102E-16"
        rpy="0 0 0" />
      <mass
        value="0.90586" />
      <inertia
        ixx="0.001566"
        ixy="1.107E-20"
        ixz="2.7438E-19"
        iyy="0.00276"
        iyz="-4.4451E-20"
        izz="0.001566" />
    </inertial>
    <visual>
      <origin
        xyz="0 0 0"
        rpy="0 0 0" />
      <geometry>
        <mesh
          filename="package://rover_description/meshes/link_FL.STL" />
      </geometry>
      <material
        name="">
        <color
          rgba="0.79216 0.81961 0.93333 1" />
      </material>
    </visual>
    <collision>
      <origin
        xyz="0 0 0"
        rpy="0 0 0" />
      <geometry>
        <mesh
          filename="package://rover_description/meshes/link_FL.STL" />
      </geometry>
    </collision>
  </link>
  <joint
    name="joint_FL"
    type="continuous">
    <origin
      xyz="0.22765 0.32735 -0.12704"
      rpy="0 0 0" />
    <parent
      link="base_link" />
    <child
      link="link_FL" />
    <axis
      xyz="0 1 0" />
  </joint>
  <link
    name="link_FR">
    <inertial>
      <origin
        xyz="-2.2204E-16 0.02376 0"
        rpy="0 0 0" />
      <mass
        value="0.90586" />
      <inertia
        ixx="0.001566"
        ixy="2.6941E-20"
        ixz="4.3411E-21"
        iyy="0.00276"
        iyz="-4.0591E-20"
        izz="0.001566" />
    </inertial>
    <visual>
      <origin
        xyz="0 0 0"
        rpy="0 0 0" />
      <geometry>
        <mesh
          filename="package://rover_description/meshes/link_FR.STL" />
      </geometry>
      <material
        name="">
        <color
          rgba="0.79216 0.81961 0.93333 1" />
      </material>
    </visual>
    <collision>
      <origin
        xyz="0 0 0"
        rpy="0 0 0" />
      <geometry>
        <mesh
          filename="package://rover_description/meshes/link_FR.STL" />
      </geometry>
    </collision>
  </link>
  <joint
    name="joint_FR"
    type="continuous">
    <origin
      xyz="0.22765 -0.32735 -0.12704"
      rpy="0 0 0" />
    <parent
      link="base_link" />
    <child
      link="link_FR" />
    <axis
      xyz="0 1 0" />
  </joint>
  <link
    name="link_BL">
    <inertial>
      <origin
        xyz="0 -0.02376 1.1102E-16"
        rpy="0 0 0" />
      <mass
        value="0.90586" />
      <inertia
        ixx="0.001566"
        ixy="-6.5434E-20"
        ixz="-4.6682E-20"
        iyy="0.00276"
        iyz="-5.054E-21"
        izz="0.001566" />
    </inertial>
    <visual>
      <origin
        xyz="0 0 0"
        rpy="0 0 0" />
      <geometry>
        <mesh
          filename="package://rover_description/meshes/link_BL.STL" />
      </geometry>
      <material
        name="">
        <color
          rgba="0.79216 0.81961 0.93333 1" />
      </material>
    </visual>
    <collision>
      <origin
        xyz="0 0 0"
        rpy="0 0 0" />
      <geometry>
        <mesh
          filename="package://rover_description/meshes/link_BL.STL" />
      </geometry>
    </collision>
  </link>
  <joint
    name="joint_BL"
    type="continuous">
    <origin
      xyz="-0.34054 0.32735 -0.12704"
      rpy="0 0 0" />
    <parent
      link="base_link" />
    <child
      link="link_BL" />
    <axis
      xyz="0 1 0" />
  </joint>
  <link
    name="link_BR">
    <inertial>
      <origin
        xyz="-2.2204E-16 0.02376 0"
        rpy="0 0 0" />
      <mass
        value="0.90586" />
      <inertia
        ixx="0.001566"
        ixy="-8.0765E-20"
        ixz="-2.3203E-19"
        iyy="0.00276"
        iyz="4.4181E-20"
        izz="0.001566" />
    </inertial>
    <visual>
      <origin
        xyz="0 0 0"
        rpy="0 0 0" />
      <geometry>
        <mesh
          filename="package://rover_description/meshes/link_BR.STL" />
      </geometry>
      <material
        name="">
        <color
          rgba="0.79216 0.81961 0.93333 1" />
      </material>
    </visual>
    <collision>
      <origin
        xyz="0 0 0"
        rpy="0 0 0" />
      <geometry>
        <mesh
          filename="package://rover_description/meshes/link_BR.STL" />
      </geometry>
    </collision>
  </link>
  <joint
    name="joint_BR"
    type="continuous">
    <origin
      xyz="-0.34054 -0.32735 -0.12704"
      rpy="0 0 0" />
    <parent
      link="base_link" />
    <child
      link="link_BR" />
    <axis
      xyz="0 1 0" />
  </joint>
</robot>